<mujoco>
  <include file="scene.xml"/>
  <include file="vx300s_dependencies.xml"/>

  <worldbody>
    <include file="vx300s_left.xml"/>
    <include file="vx300s_right.xml"/>

    <body name="cover" pos="0.4 0.5 0.1">
      <joint name="cover_joint" type="hinge" axis="0 1 0" pos="0 0 0" range="-1.57 0"/>
      <inertial pos="0 0 0" mass="0.02" diaginertia="0.0001 0.0001 0.0001"/>
      <geom name="cover_geom" type="box" size="0.05 0.02 0.005" pos="0 0 0"
            rgba="0.7 0.7 0.7 1" solimp="0.25 0.25 0.001" solref="0.01 1" friction="1 0.005 0.0001"/>
    </body>

    <body name="charging_gun" pos="0.3 0.5 0.05">
      <joint name="charging_gun_joint" type="free" frictionloss="0.01"/>
      <inertial pos="0 0 0" mass="0.2" diaginertia="0.005 0.005 0.005"/>
      <geom name="gun_geom" type="box" size="0.02 0.02 0.06" pos="0 0 0"
            rgba="0.2 0.2 0.2 1" solimp="2 1 0.01" solref="0.01 1" friction="1 0.005 0.0001"/>
    </body>

    <body name="port_inner" pos="0.45 0.5 0.1">
      <joint name="port_inner_joint" type="free"/>
      <geom name="port_inner" type="cylinder" size="0.01 0.02" pos="0 0 0" rgba="0 0 1 0.5"/>
    </body>
  </worldbody>

  <equality>
    <weld body1="mocap_right" body2="cover" solref="0.01 1" solimp="0.25 0.25 0.001"/>
    <weld body1="mocap_left"  body2="charging_gun" solref="0.01 1" solimp="0.25 0.25 0.001"/>
  </equality>

  <actuator>
    <position joint="vx300s_left/left_finger"  ctrllimited="true" ctrlrange="0.021 0.057" kp="200" user="1"/>
    <position joint="vx300s_left/right_finger" ctrllimited="true" ctrlrange="-0.057 -0.021" kp="200" user="1"/>
    <position joint="vx300s_right/left_finger" ctrllimited="true" ctrlrange="0.021 0.057" kp="200" user="1"/>
    <position joint="vx300s_right/right_finger"ctrllimited="true" ctrlrange="-0.057 -0.021" kp="200" user="1"/>
  </actuator>
</mujoco>
